Workbook
Name Slicer_Department: #N/A
Name Slicer_Superviors_Status: #N/A
Name Slicer_Years_of_Service: #N/A

Sheet RawData
A1: ID | B1: Staff Name | C1: Department | D1: Division | E1: Years of Service | F1: Sort by YOS | G1: Supervisor | H1: Superviors Status | I1: Aware: Safety & Wellness Office | J1: Aware: Monthly Meetings | K1: Awareness Status | L1: Attended in Past 3 Years | M1: Attendance Status | N1: Reason for Not Attending (open) | O1: Barrier (What Prevented You) | P1: Interest in Future Meetings (Yes/No) | Q1: Would You Be Interested? (Yes/No/Unsure/Unsure)
A2: 1 | B2: Staff_021 | C2: Administration | D2: Division 080 | E2: <1 | F2: =MATCH(Table[[#This Row],[Years of Service]], {"<1","1-5","6-10","11-20","21-30","31-40","40+"}, 0) -> 1 | G2: Yes | H2: Supervisor | I2: Yes | J2: Yes | K2: {=_xlfn.IFS(AND(Table[[#This Row],[Aware: Safety & Wellness Office]]="Yes",Table[[#This Row],[Aware: Monthly Meetings]]="Yes"), "Aware of office & meeting", AND(Table[[#This Row],[Aware: Safety & Wellness Office]]="Yes", Table[[#This Row],[Aware: Monthly Meetings]]="No"), "Aware of office", AND(Table[[#This Row],[Aware: Safety & Wellness Office]]="No", Table[[#This Row],[Aware: Monthly Meetings]]="Yes"), "Aware of meeting", AND(Table[[#This Row],[Aware: Safety & Wellness Office]]="No", Table[[#This Row],[Aware: Monthly Meetings]]="No"),"Unaware of office & meeting", TRUE, "Check Data")} -> Aware of office & meeting | L2: Yes | M2: {=_xlfn.IFS(AND(Table[[#This Row],[Aware: Safety & Wellness Office]]="Yes",Table[[#This Row],[Aware: Monthly Meetings]]="Yes",Table[[#This Row],[Attended in Past 3 Years]]="Yes"), "Aware Attendee", AND(Table[[#This Row],[Aware: Safety & Wellness Office]]="Yes",Table[[#This Row],[Aware: Monthly Meetings]]="No",Table[[#This Row],[Attended in Past 3 Years]]="Yes"), "Office Aware Attendee", AND(Table[[#This Row],[Aware: Safety & Wellness Office]]="No",Table[[#This Row],[Aware: Monthly Meetings]]="Yes",Table[[#This Row],[Attended in Past 3 Years]]="Yes"), "Meeting Aware Attendee", AND(Table[[#This Row],[Aware: Safety & Wellness Office]]="No",Table[[#This Row],[Aware: Monthly Meetings]]="No",Table[[#This Row],[Attended in Past 3 Years]]="Yes"), "Unaware Attendee", AND(Table[[#This Row],[Aware: Safety & Wellness Office]]="No",Table[[#This Row],[Aware: Monthly Meetings]]="No",Table[[#This Row],[Attended in Past 3 Years]]="No"), "Unaware Non-attendee", AND(Table[[#This Row],[Aware: Safety & Wellness Office]]="Yes",Table[[#This Row],[Aware: Monthly Meetings]]="No",Table[[#This Row],[Attended in Past 3 Years]]="No"), "Office Aware Non-attendee", AND(Table[[#This Row],[Aware: Safety & Wellness Office]]="No",Table[[#This Row],[Aware: Monthly Meetings]]="Yes",Table[[#This Row],[Attended in Past 3 Years]]="No"), "Meeting Aware Non-attendee", AND(Table[[#This Row],[Aware: Safety & Wellness Office]]="Yes",Table[[#This Row],[Aware: Monthly Meetings]]="Yes",Table[[#This Row],[Attended in Past 3 Years]]="No"), "Aware Non-attendee", TRUE, "Check Data")} -> Aware Attendee | O2: NA | P2: Yes | Q2: Yes
A3: 2 | B3: Staff_041 | C3: Sales & Marketing | D3: Division 046 | E3: <1 | F3: =MATCH(Table[[#This Row],[Years of Service]], {"<1","1-5","6-10","11-20","21-30","31-40","40+"}, 0) -> 1 | G3: No | H3: Non-supervisor | I3: No | J3: No | K3: {=_xlfn.IFS(AND(Table[[#This Row],[Aware: Safety & Wellness Office]]="Yes",Table[[#This Row],[Aware: Monthly Meetings]]="Yes"), "Aware of office & meeting", AND(Table[[#This Row],[Aware: Safety & Wellness Office]]="Yes", Table[[#This Row],[Aware: Monthly Meetings]]="No"), "Aware of office", AND(Table[[#This Row],[Aware: Safety & Wellness Office]]="No", Table[[#This Row],[Aware: Monthly Meetings]]="Yes"), "Aware of meeting", AND(Table[[#This Row],[Aware: Safety & Wellness Office]]="No", Table[[#This Row],[Aware: Monthly Meetings]]="No"),"Unaware of office & meeting", TRUE, "Check Data")} -> Unaware of office & meeting | L3: No | M3: {=_xlfn.IFS(AND(Table[[#This Row],[Aware: Safety & Wellness Office]]="Yes",Table[[#This Row],[Aware: Monthly Meetings]]="Yes",Table[[#This Row],[Attended in Past 3 Years]]="Yes"), "Aware Attendee", AND(Table[[#This Row],[Aware: Safety & Wellness Office]]="Yes",Table[[#This Row],[Aware: Monthly Meetings]]="No",Table[[#This Row],[Attended in Past 3 Years]]="Yes"), "Office Aware Attendee", AND(Table[[#This Row],[Aware: Safety & Wellness Office]]="No",Table[[#This Row],[Aware: Monthly Meetings]]="Yes",Table[[#This Row],[Attended in Past 3 Years]]="Yes"), "Meeting Aware Attendee", AND(Table[[#This Row],[Aware: Safety & Wellness Office]]="No",Table[[#This Row],[Aware: Monthly Meetings]]="No",Table[[#This Row],[Attended in Past 3 Years]]="Yes"), "Unaware Attendee", AND(Table[[#This Row],[Aware: Safety & Wellness Office]]="No",Table[[#This Row],[Aware: Monthly Meetings]]="No",Table[[#This Row],[Attended in Past 3 Years]]="No"), "Unaware Non-attendee", AND(Table[[#This Row],[Aware: Safety & Wellness Office]]="Yes",Table[[#This Row],[Aware: Monthly Meetings]]="No",Table[[#This Row],[Attended in Past 3 Years]]="No"), "Office Aware Non-attendee", AND(Table[[#This Row],[Aware: Safety & Wellness Office]]="No",Table[[#This Row],[Aware: Monthly Meetings]]="Yes",Table[[#This Row],[Attended in Past 3 Years]]="No"), "Meeting Aware Non-attendee", AND(Table[[#This Row],[Aware: Safety & Wellness Office]]="Yes",Table[[#This Row],[Aware: Monthly Meetings]]="Yes",Table[[#This Row],[Attended in Past 3 Years]]="No"), "Aware Non-attendee", TRUE, "Check Data")} -> Unaware Non-attendee | N3: Time conflict with shift | O3: Time conflict | P3: No | Q3: Unsure
A4: 3 | B4: Staff_043 | C4: Administration | D4: Division 084 | E4: <1 | F4: =MATCH(Table[[#This Row],[Years of Service]], {"<1","1-5","6-10","11-20","21-30","31-40","40+"}, 0) -> 1 | G4: Yes | H4: Supervisor | I4: Yes | J4: Yes | K4: {=_xlfn.IFS(AND(Table[[#This Row],[Aware: Safety & Wellness Office]]="Yes",Table[[#This Row],[Aware: Monthly Meetings]]="Yes"), "Aware of office & meeting", AND(Table[[#This Row],[Aware: Safety & Wellness Office]]="Yes", Table[[#This Row],[Aware: Monthly Meetings]]="No"), "Aware of office", AND(Table[[#This Row],[Aware: Safety & Wellness Office]]="No", Table[[#This Row],[Aware: Monthly Meetings]]="Yes"), "Aware of meeting", AND(Table[[#This Row],[Aware: Safety & Wellness Office]]="No", Table[[#This Row],[Aware: Monthly Meetings]]="No"),"Unaware of office & meeting", TRUE, "Check Data")} -> Aware of office & meeting | L4: No | M4: {=_xlfn.IFS(AND(Table[[#This Row],[Aware: Safety & Wellness Office]]="Yes",Table[[#This Row],[Aware: Monthly Meetings]]="Yes",Table[[#This Row],[Attended in Past 3 Years]]="Yes"), "Aware Attendee", AND(Table[[#This Row],[Aware: Safety & Wellness Office]]="Yes",Table[[#This Row],[Aware: Monthly Meetings]]="No",Table[[#This Row],[Attended in Past 3 Years]]="Yes"), "Office Aware Attendee", AND(Table[[#This Row],[Aware: Safety & Wellness Office]]="No",Table[[#This Row],[Aware: Monthly Meetings]]="Yes",Table[[#This Row],[Attended in Past 3 Years]]="Yes"), "Meeting Aware Attendee", AND(Table[[#This Row],[Aware: Safety & Wellness Office]]="No",Table[[#This Row],[Aware: Monthly Meetings]]="No",Table[[#This Row],[Attended in Past 3 Years]]="Yes"), "Unaware Attendee", AND(Table[[#This Row],[Aware: Safety & Wellness Office]]="No",Table[[#This Row],[Aware: Monthly Meetings]]="No",Table[[#This Row],[Attended in Past 3 Years]]="No"), "Unaware Non-attendee", AND(Table[[#This Row],[Aware: Safety & Wellness Office]]="Yes",Table[[#This Row],[Aware: Monthly Meetings]]="No",Table[[#This Row],[Attended in Past 3 Years]]="No"), "Office Aware Non-attendee", AND(Table[[#This Row],[Aware: Safety & Wellness Office]]="No",Table[[#This Row],[Aware: Monthly Meetings]]="Yes",Table[[#This Row],[Attended in Past 3 Years]]="No"), "Meeting Aware Non-attendee", AND(Table[[#This Row],[Aware: Safety & Wellness Office]]="Yes",Table[[#This Row],[Aware: Monthly Meetings]]="Yes",Table[[#This Row],[Attended in Past 3 Years]]="No"), "Aware Non-attendee", TRUE, "Check Data")} -> Aware Non-attendee | N4: Location too far | O4: NA | P4: Yes | Q4: Yes
A5: 4 | B5: Staff_044 | C5: Administration | D5: Division 033 | E5: <1 | F5: =MATCH(Table[[#This Row],[Years of Service]], {"<1","1-5","6-10","11-20","21-30","31-40","40+"}, 0) -> 1 | G5: Yes | H5: Supervisor | I5: Yes | J5: No | K5: {=_xlfn.IFS(AND(Table[[#This Row],[Aware: Safety & Wellness Office]]="Yes",Table[[#This Row],[Aware: Monthly Meetings]]="Yes"), "Aware of office & meeting", AND(Table[[#This Row],[Aware: Safety & Wellness Office]]="Yes", Table[[#This Row],[Aware: Monthly Meetings]]="No"), "Aware of office", AND(Table[[#This Row],[Aware: Safety & Wellness Office]]="No", Table[[#This Row],[Aware: Monthly Meetings]]="Yes"), "Aware of meeting", AND(Table[[#This Row],[Aware: Safety & Wellness Office]]="No", Table[[#This Row],[Aware: Monthly Meetings]]="No"),"Unaware of office & meeting", TRUE, "Check Data")} -> Aware of office | L5: No | M5: {=_xlfn.IFS(AND(Table[[#This Row],[Aware: Safety & Wellness Office]]="Yes",Table[[#This Row],[Aware: Monthly Meetings]]="Yes",Table[[#This Row],[Attended in Past 3 Years]]="Yes"), "Aware Attendee", AND(Table[[#This Row],[Aware: Safety & Wellness Office]]="Yes",Table[[#This Row],[Aware: Monthly Meetings]]="No",Table[[#This Row],[Attended in Past 3 Years]]="Yes"), "Office Aware Attendee", AND(Table[[#This Row],[Aware: Safety & Wellness Office]]="No",Table[[#This Row],[Aware: Monthly Meetings]]="Yes",Table[[#This Row],[Attended in Past 3 Years]]="Yes"), "Meeting Aware Attendee", AND(Table[[#This Row],[Aware: Safety & Wellness Office]]="No",Table[[#This Row],[Aware: Monthly Meetings]]="No",Table[[#This Row],[Attended in Past 3 Years]]="Yes"), "Unaware Attendee", AND(Table[[#This Row],[Aware: Safety & Wellness Office]]="No",Table[[#This Row],[Aware: Monthly Meetings]]="No",Table[[#This Row],[Attended in Past 3 Years]]="No"), "Unaware Non-attendee", AND(Table[[#This Row],[Aware: Safety & Wellness Office]]="Yes",Table[[#This Row],[Aware: Monthly Meetings]]="No",Table[[#This Row],[Attended in Past 3 Years]]="No"), "Office Aware Non-attendee", AND(Table[[#This Row],[Aware: Safety & Wellness Office]]="No",Table[[#This Row],[Aware: Monthly Meetings]]="Yes",Table[[#This Row],[Attended in Past 3 Years]]="No"), "Meeting Aware Non-attendee", AND(Table[[#This Row],[Aware: Safety & Wellness Office]]="Yes",Table[[#This Row],[Aware: Monthly Meetings]]="Yes",Table[[#This Row],[Attended in Past 3 Years]]="No"), "Aware Non-attendee", TRUE, "Check Data")} -> Office Aware Non-attendee | N5: Unaware of meeting schedule | O5: Unaware | P5: Yes | Q5: Unsure
A6: 5 | B6: Staff_056 | C6: Sales & Marketing | D6: Division 093 | E6: <1 | F6: =MATCH(Table[[#This Row],[Years of Service]], {"<1","1-5","6-10","11-20","21-30","31-40","40+"}, 0) -> 1 | G6: No | H6: Non-supervisor | I6: Yes | J6: Yes | K6: {=_xlfn.IFS(AND(Table[[#This Row],[Aware: Safety & Wellness Office]]="Yes",Table[[#This Row],[Aware: Monthly Meetings]]="Yes"), "Aware of office & meeting", AND(Table[[#This Row],[Aware: Safety & Wellness Office]]="Yes", Table[[#This Row],[Aware: Monthly Meetings]]="No"), "Aware of office", AND(Table[[#This Row],[Aware: Safety & Wellness Office]]="No", Table[[#This Row],[Aware: Monthly Meetings]]="Yes"), "Aware of meeting", AND(Table[[#This Row],[Aware: Safety & Wellness Office]]="No", Table[[#This Row],[Aware: Monthly Meetings]]="No"),"Unaware of office & meeting", TRUE, "Check Data")} -> Aware of office & meeting | L6: No | M6: {=_xlfn.IFS(AND(Table[[#This Row],[Aware: Safety & Wellness Office]]="Yes",Table[[#This Row],[Aware: Monthly Meetings]]="Yes",Table[[#This Row],[Attended in Past 3 Years]]="Yes"), "Aware Attendee", AND(Table[[#This Row],[Aware: Safety & Wellness Office]]="Yes",Table[[#This Row],[Aware: Monthly Meetings]]="No",Table[[#This Row],[Attended in Past 3 Years]]="Yes"), "Office Aware Attendee", AND(Table[[#This Row],[Aware: Safety & Wellness Office]]="No",Table[[#This Row],[Aware: Monthly Meetings]]="Yes",Table[[#This Row],[Attended in Past 3 Years]]="Yes"), "Meeting Aware Attendee", AND(Table[[#This Row],[Aware: Safety & Wellness Office]]="No",Table[[#This Row],[Aware: Monthly Meetings]]="No",Table[[#This Row],[Attended in Past 3 Years]]="Yes"), "Unaware Attendee", AND(Table[[#This Row],[Aware: Safety & Wellness Office]]="No",Table[[#This Row],[Aware: Monthly Meetings]]="No",Table[[#This Row],[Attended in Past 3 Years]]="No"), "Unaware Non-attendee", AND(Table[[#This Row],[Aware: Safety & Wellness Office]]="Yes",Table[[#This Row],[Aware: Monthly Meetings]]="No",Table[[#This Row],[Attended in Past 3 Years]]="No"), "Office Aware Non-attendee", AND(Table[[#This Row],[Aware: Safety & Wellness Office]]="No",Table[[#This Row],[Aware: Monthly Meetings]]="Yes",Table[[#This Row],[Attended in Past 3 Years]]="No"), "Meeting Aware Non-attendee", AND(Table[[#This Row],[Aware: Safety & Wellness Office]]="Yes",Table[[#This Row],[Aware: Monthly Meetings]]="Yes",Table[[#This Row],[Attended in Past 3 Years]]="No"), "Aware Non-attendee", TRUE, "Check Data")} -> Aware Non-attendee | N6: Out on leave / travel | O6: Time conflict | P6: Yes | Q6: Unsure
A7: 6 | B7: Staff_065 | C7: Repairs | D7: Division 048 | E7: <1 | F7: =MATCH(Table[[#This Row],[Years of Service]], {"<1","1-5","6-10","11-20","21-30","31-40","40+"}, 0) -> 1 | G7: No | H7: Non-supervisor | I7: Yes | J7: No | K7: {=_xlfn.IFS(AND(Table[[#This Row],[Aware: Safety & Wellness Office]]="Yes",Table[[#This Row],[Aware: Monthly Meetings]]="Yes"), "Aware of office & meeting", AND(Table[[#This Row],[Aware: Safety & Wellness Office]]="Yes", Table[[#This Row],[Aware: Monthly Meetings]]="No"), "Aware of office", AND(Table[[#This Row],[Aware: Safety & Wellness Office]]="No", Table[[#This Row],[Aware: Monthly Meetings]]="Yes"), "Aware of meeting", AND(Table[[#This Row],[Aware: Safety & Wellness Office]]="No", Table[[#This Row],[Aware: Monthly Meetings]]="No"),"Unaware of office & meeting", TRUE, "Check Data")} -> Aware of office | L7: No | M7: {=_xlfn.IFS(AND(Table[[#This Row],[Aware: Safety & Wellness Office]]="Yes",Table[[#This Row],[Aware: Monthly Meetings]]="Yes",Table[[#This Row],[Attended in Past 3 Years]]="Yes"), "Aware Attendee", AND(Table[[#This Row],[Aware: Safety & Wellness Office]]="Yes",Table[[#This Row],[Aware: Monthly Meetings]]="No",Table[[#This Row],[Attended in Past 3 Years]]="Yes"), "Office Aware Attendee", AND(Table[[#This Row],[Aware: Safety & Wellness Office]]="No",Table[[#This Row],[Aware: Monthly Meetings]]="Yes",Table[[#This Row],[Attended in Past 3 Years]]="Yes"), "Meeting Aware Attendee", AND(Table[[#This Row],[Aware: Safety & Wellness Office]]="No",Table[[#This Row],[Aware: Monthly Meetings]]="No",Table[[#This Row],[Attended in Past 3 Years]]="Yes"), "Unaware Attendee", AND(Table[[#This Row],[Aware: Safety & Wellness Office]]="No",Table[[#This Row],[Aware: Monthly Meetings]]="No",Table[[#This Row],[Attended in Past 3 Years]]="No"), "Unaware Non-attendee", AND(Table[[#This Row],[Aware: Safety & Wellness Office]]="Yes",Table[[#This Row],[Aware: Monthly Meetings]]="No",Table[[#This Row],[Attended in Past 3 Years]]="No"), "Office Aware Non-attendee", AND(Table[[#This Row],[Aware: Safety & Wellness Office]]="No",Table[[#This Row],[Aware: Monthly Meetings]]="Yes",Table[[#This Row],[Attended in Past 3 Years]]="No"), "Meeting Aware Non-attendee", AND(Table[[#This Row],[Aware: Safety & Wellness Office]]="Yes",Table[[#This Row],[Aware: Monthly Meetings]]="Yes",Table[[#This Row],[Attended in Past 3 Years]]="No"), "Aware Non-attendee", TRUE, "Check Data")} -> Office Aware Non-attendee | N7: Unaware of meeting schedule | O7: Unaware | P7: Yes | Q7: Yes
A8: 7 | B8: Staff_080 | C8: Administration | D8: Division 059 | E8: <1 | F8: =MATCH(Table[[#This Row],[Years of Service]], {"<1","1-5","6-10","11-20","21-30","31-40","40+"}, 0) -> 1 | G8: No | H8: Non-supervisor | I8: No | J8: No | K8: {=_xlfn.IFS(AND(Table[[#This Row],[Aware: Safety & Wellness Office]]="Yes",Table[[#This Row],[Aware: Monthly Meetings]]="Yes"), "Aware of office & meeting", AND(Table[[#This Row],[Aware: Safety & Wellness Office]]="Yes", Table[[#This Row],[Aware: Monthly Meetings]]="No"), "Aware of office", AND(Table[[#This Row],[Aware: Safety & Wellness Office]]="No", Table[[#This Row],[Aware: Monthly Meetings]]="Yes"), "Aware of meeting", AND(Table[[#This Row],[Aware: Safety & Wellness Office]]="No", Table[[#This Row],[Aware: Monthly Meetings]]="No"),"Unaware of office & meeting", TRUE, "Check Data")} -> Unaware of office & meeting | L8: No | M8: {=_xlfn.IFS(AND(Table[[#This Row],[Aware: Safety & Wellness Office]]="Yes",Table[[#This Row],[Aware: Monthly Meetings]]="Yes",Table[[#This Row],[Attended in Past 3 Years]]="Yes"), "Aware Attendee", AND(Table[[#This Row],[Aware: Safety & Wellness Office]]="Yes",Table[[#This Row],[Aware: Monthly Meetings]]="No",Table[[#This Row],[Attended in Past 3 Years]]="Yes"), "Office Aware Attendee", AND(Table[[#This Row],[Aware: Safety & Wellness Office]]="No",Table[[#This Row],[Aware: Monthly Meetings]]="Yes",Table[[#This Row],[Attended in Past 3 Years]]="Yes"), "Meeting Aware Attendee", AND(Table[[#This Row],[Aware: Safety & Wellness Office]]="No",Table[[#This Row],[Aware: Monthly Meetings]]="No",Table[[#This Row],[Attended in Past 3 Years]]="Yes"), "Unaware Attendee", AND(Table[[#This Row],[Aware: Safety & Wellness Office]]="No",Table[[#This Row],[Aware: Monthly Meetings]]="No",Table[[#This Row],[Attended in Past 3 Years]]="No"), "Unaware Non-attendee", AND(Table[[#This Row],[Aware: Safety & Wellness Office]]="Yes",Table[[#This Row],[Aware: Monthly Meetings]]="No",Table[[#This Row],[Attended in Past 3 Years]]="No"), "Office Aware Non-attendee", AND(Table[[#This Row],[Aware: Safety & Wellness Office]]="No",Table[[#This Row],[Aware: Monthly Meetings]]="Yes",Table[[#This Row],[Attended in Past 3 Years]]="No"), "Meeting Aware Non-attendee", AND(Table[[#This Row],[Aware: Safety & Wellness Office]]="Yes",Table[[#This Row],[Aware: Monthly Meetings]]="Yes",Table[[#This Row],[Attended in Past 3 Years]]="No"), "Aware Non-attendee", TRUE, "Check Data")} -> Unaware Non-attendee | N8: Unaware of meeting schedule | O8: Unaware | P8: Yes | Q8: Unsure
A9: 8 | B9: Staff_086 | C9: Sales & Marketing | D9: Division 010 | E9: <1 | F9: =MATCH(Table[[#This Row],[Years of Service]], {"<1","1-5","6-10","11-20","21-30","31-40","40+"}, 0) -> 1 | G9: Yes | H9: Supervisor | I9: Yes | J9: Yes | K9: {=_xlfn.IFS(AND(Table[[#This Row],[Aware: Safety & Wellness Office]]="Yes",Table[[#This Row],[Aware: Monthly Meetings]]="Yes"), "Aware of office & meeting", AND(Table[[#This Row],[Aware: Safety & Wellness Office]]="Yes", Table[[#This Row],[Aware: Monthly Meetings]]="No"), "Aware of office", AND(Table[[#This Row],[Aware: Safety & Wellness Office]]="No", Table[[#This Row],[Aware: Monthly Meetings]]="Yes"), "Aware of meeting", AND(Table[[#This Row],[Aware: Safety & Wellness Office]]="No", Table[[#This Row],[Aware: Monthly Meetings]]="No"),"Unaware of office & meeting", TRUE, "Check Data")} -> Aware of office & meeting | L9: No | M9: {=_xlfn.IFS(AND(Table[[#This Row],[Aware: Safety & Wellness Office]]="Yes",Table[[#This Row],[Aware: Monthly Meetings]]="Yes",Table[[#This Row],[Attended in Past 3 Years]]="Yes"), "Aware Attendee", AND(Table[[#This Row],[Aware: Safety & Wellness Office]]="Yes",Table[[#This Row],[Aware: Monthly Meetings]]="No",Table[[#This Row],[Attended in Past 3 Years]]="Yes"), "Office Aware Attendee", AND(Table[[#This Row],[Aware: Safety & Wellness Office]]="No",Table[[#This Row],[Aware: Monthly Meetings]]="Yes",Table[[#This Row],[Attended in Past 3 Years]]="Yes"), "Meeting Aware Attendee", AND(Table[[#This Row],[Aware: Safety & Wellness Office]]="No",Table[[#This Row],[Aware: Monthly Meetings]]="No",Table[[#This Row],[Attended in Past 3 Years]]="Yes"), "Unaware Attendee", AND(Table[[#This Row],[Aware: Safety & Wellness Office]]="No",Table[[#This Row],[Aware: Monthly Meetings]]="No",Table[[#This Row],[Attended in Past 3 Years]]="No"), "Unaware Non-attendee", AND(Table[[#This Row],[Aware: Safety & Wellness Office]]="Yes",Table[[#This Row],[Aware: Monthly Meetings]]="No",Table[[#This Row],[Attended in Past 3 Years]]="No"), "Office Aware Non-attendee", AND(Table[[#This Row],[Aware: Safety & Wellness Office]]="No",Table[[#This Row],[Aware: Monthly Meetings]]="Yes",Table[[#This Row],[Attended in Past 3 Years]]="No"), "Meeting Aware Non-attendee", AND(Table[[#This Row],[Aware: Safety & Wellness Office]]="Yes",Table[[#This Row],[Aware: Monthly Meetings]]="Yes",Table[[#This Row],[Attended in Past 3 Years]]="No"), "Aware Non-attendee", TRUE, "Check Data")} -> Aware Non-attendee | N9: Location too far | O9: Unaware | P9: Yes | Q9: Yes
A10: 9 | B10: Staff_003 | C10: Administration | D10: Division 083 | E10: 1-5 | F10: =MATCH(Table[[#This Row],[Years of Service]], {"<1","1-5","6-10","11-20","21-30","31-40","40+"}, 0) -> 2 | G10: No | H10: Non-supervisor | I10: Yes | J10: Yes | K10: {=_xlfn.IFS(AND(Table[[#This Row],[Aware: Safety & Wellness Office]]="Yes",Table[[#This Row],[Aware: Monthly Meetings]]="Yes"), "Aware of office & meeting", AND(Table[[#This Row],[Aware: Safety & Wellness Office]]="Yes", Table[[#This Row],[Aware: Monthly Meetings]]="No"), "Aware of office", AND(Table[[#This Row],[Aware: Safety & Wellness Office]]="No", Table[[#This Row],[Aware: Monthly Meetings]]="Yes"), "Aware of meeting", AND(Table[[#This Row],[Aware: Safety & Wellness Office]]="No", Table[[#This Row],[Aware: Monthly Meetings]]="No"),"Unaware of office & meeting", TRUE, "Check Data")} -> Aware of office & meeting | L10: Yes | M10: {=_xlfn.IFS(AND(Table[[#This Row],[Aware: Safety & Wellness Office]]="Yes",Table[[#This Row],[Aware: Monthly Meetings]]="Yes",Table[[#This Row],[Attended in Past 3 Years]]="Yes"), "Aware Attendee", AND(Table[[#This Row],[Aware: Safety & Wellness Office]]="Yes",Table[[#This Row],[Aware: Monthly Meetings]]="No",Table[[#This Row],[Attended in Past 3 Years]]="Yes"), "Office Aware Attendee", AND(Table[[#This Row],[Aware: Safety & Wellness Office]]="No",Table[[#This Row],[Aware: Monthly Meetings]]="Yes",Table[[#This Row],[Attended in Past 3 Years]]="Yes"), "Meeting Aware Attendee", AND(Table[[#This Row],[Aware: Safety & Wellness Office]]="No",Table[[#This Row],[Aware: Monthly Meetings]]="No",Table[[#This Row],[Attended in Past 3 Years]]="Yes"), "Unaware Attendee", AND(Table[[#This Row],[Aware: Safety & Wellness Office]]="No",Table[[#This Row],[Aware: Monthly Meetings]]="No",Table[[#This Row],[Attended in Past 3 Years]]="No"), "Unaware Non-attendee", AND(Table[[#This Row],[Aware: Safety & Wellness Office]]="Yes",Table[[#This Row],[Aware: Monthly Meetings]]="No",Table[[#This Row],[Attended in Past 3 Years]]="No"), "Office Aware Non-attendee", AND(Table[[#This Row],[Aware: Safety & Wellness Office]]="No",Table[[#This Row],[Aware: Monthly Meetings]]="Yes",Table[[#This Row],[Attended in Past 3 Years]]="No"), "Meeting Aware Non-attendee", AND(Table[[#This Row],[Aware: Safety & Wellness Office]]="Yes",Table[[#This Row],[Aware: Monthly Meetings]]="Yes",Table[[#This Row],[Attended in Past 3 Years]]="No"), "Aware Non-attendee", TRUE, "Check Data")} -> Aware Attendee | O10: NA | P10: Yes | Q10: Yes
A11: 10 | B11: Staff_006 | C11: Repairs | D11: Division 055 | E11: 1-5 | F11: =MATCH(Table[[#This Row],[Years of Service]], {"<1","1-5","6-10","11-20","21-30","31-40","40+"}, 0) -> 2 | G11: No | H11: Non-supervisor | I11: Yes | J11: Yes | K11: {=_xlfn.IFS(AND(Table[[#This Row],[Aware: Safety & Wellness Office]]="Yes",Table[[#This Row],[Aware: Monthly Meetings]]="Yes"), "Aware of office & meeting", AND(Table[[#This Row],[Aware: Safety & Wellness Office]]="Yes", Table[[#This Row],[Aware: Monthly Meetings]]="No"), "Aware of office", AND(Table[[#This Row],[Aware: Safety & Wellness Office]]="No", Table[[#This Row],[Aware: Monthly Meetings]]="Yes"), "Aware of meeting", AND(Table[[#This Row],[Aware: Safety & Wellness Office]]="No", Table[[#This Row],[Aware: Monthly Meetings]]="No"),"Unaware of office & meeting", TRUE, "Check Data")} -> Aware of office & meeting | L11: No | M11: {=_xlfn.IFS(AND(Table[[#This Row],[Aware: Safety & Wellness Office]]="Yes",Table[[#This Row],[Aware: Monthly Meetings]]="Yes",Table[[#This Row],[Attended in Past 3 Years]]="Yes"), "Aware Attendee", AND(Table[[#This Row],[Aware: Safety & Wellness Office]]="Yes",Table[[#This Row],[Aware: Monthly Meetings]]="No",Table[[#This Row],[Attended in Past 3 Years]]="Yes"), "Office Aware Attendee", AND(Table[[#This Row],[Aware: Safety & Wellness Office]]="No",Table[[#This Row],[Aware: Monthly Meetings]]="Yes",Table[[#This Row],[Attended in Past 3 Years]]="Yes"), "Meeting Aware Attendee", AND(Table[[#This Row],[Aware: Safety & Wellness Office]]="No",Table[[#This Row],[Aware: Monthly Meetings]]="No",Table[[#This Row],[Attended in Past 3 Years]]="Yes"), "Unaware Attendee", AND(Table[[#This Row],[Aware: Safety & Wellness Office]]="No",Table[[#This Row],[Aware: Monthly Meetings]]="No",Table[[#This Row],[Attended in Past 3 Years]]="No"), "Unaware Non-attendee", AND(Table[[#This Row],[Aware: Safety & Wellness Office]]="Yes",Table[[#This Row],[Aware: Monthly Meetings]]="No",Table[[#This Row],[Attended in Past 3 Years]]="No"), "Office Aware Non-attendee", AND(Table[[#This Row],[Aware: Safety & Wellness Office]]="No",Table[[#This Row],[Aware: Monthly Meetings]]="Yes",Table[[#This Row],[Attended in Past 3 Years]]="No"), "Meeting Aware Non-attendee", AND(Table[[#This Row],[Aware: Safety & Wellness Office]]="Yes",Table[[#This Row],[Aware: Monthly Meetings]]="Yes",Table[[#This Row],[Attended in Past 3 Years]]="No"), "Aware Non-attendee", TRUE, "Check Data")} -> Aware Non-attendee | N11: Time conflict with shift | O11: Time conflict | P11: Yes | Q11: Yes
A12: 11 | B12: Staff_008 | C12: Sales & Marketing | D12: Division 087 | E12: 1-5 | F12: =MATCH(Table[[#This Row],[Years of Service]], {"<1","1-5","6-10","11-20","21-30","31-40","40+"}, 0) -> 2 | G12: No | H12: Non-supervisor | I12: No | J12: No | K12: {=_xlfn.IFS(AND(Table[[#This Row],[Aware: Safety & Wellness Office]]="Yes",Table[[#This Row],[Aware: Monthly Meetings]]="Yes"), "Aware of office & meeting", AND(Table[[#This Row],[Aware: Safety & Wellness Office]]="Yes", Table[[#This Row],[Aware: Monthly Meetings]]="No"), "Aware of office", AND(Table[[#This Row],[Aware: Safety & Wellness Office]]="No", Table[[#This Row],[Aware: Monthly Meetings]]="Yes"), "Aware of meeting", AND(Table[[#This Row],[Aware: Safety & Wellness Office]]="No", Table[[#This Row],[Aware: Monthly Meetings]]="No"),"Unaware of office & meeting", TRUE, "Check Data")} -> Unaware of office & meeting | L12: No | M12: {=_xlfn.IFS(AND(Table[[#This Row],[Aware: Safety & Wellness Office]]="Yes",Table[[#This Row],[Aware: Monthly Meetings]]="Yes",Table[[#This Row],[Attended in Past 3 Years]]="Yes"), "Aware Attendee", AND(Table[[#This Row],[Aware: Safety & Wellness Office]]="Yes",Table[[#This Row],[Aware: Monthly Meetings]]="No",Table[[#This Row],[Attended in Past 3 Years]]="Yes"), "Office Aware Attendee", AND(Table[[#This Row],[Aware: Safety & Wellness Office]]="No",Table[[#This Row],[Aware: Monthly Meetings]]="Yes",Table[[#This Row],[Attended in Past 3 Years]]="Yes"), "Meeting Aware Attendee", AND(Table[[#This Row],[Aware: Safety & Wellness Office]]="No",Table[[#This Row],[Aware: Monthly Meetings]]="No",Table[[#This Row],[Attended in Past 3 Years]]="Yes"), "Unaware Attendee", AND(Table[[#This Row],[Aware: Safety & Wellness Office]]="No",Table[[#This Row],[Aware: Monthly Meetings]]="No",Table[[#This Row],[Attended in Past 3 Years]]="No"), "Unaware Non-attendee", AND(Table[[#This Row],[Aware: Safety & Wellness Office]]="Yes",Table[[#This Row],[Aware: Monthly Meetings]]="No",Table[[#This Row],[Attended in Past 3 Years]]="No"), "Office Aware Non-attendee", AND(Table[[#This Row],[Aware: Safety & Wellness Office]]="No",Table[[#This Row],[Aware: Monthly Meetings]]="Yes",Table[[#This Row],[Attended in Past 3 Years]]="No"), "Meeting Aware Non-attendee", AND(Table[[#This Row],[Aware: Safety & Wellness Office]]="Yes",Table[[#This Row],[Aware: Monthly Meetings]]="Yes",Table[[#This Row],[Attended in Past 3 Years]]="No"), "Aware Non-attendee", TRUE, "Check Data")} -> Unaware Non-attendee | N12: Unaware of meeting schedule | O12: Unaware | P12: Yes | Q12: Yes
A13: 12 | B13: Staff_009 | C13: Repairs | D13: Division 040 | E13: 1-5 | F13: =MATCH(Table[[#This Row],[Years of Service]], {"<1","1-5","6-10","11-20","21-30","31-40","40+"}, 0) -> 2 | G13: No | H13: Non-supervisor | I13: Yes | J13: Yes | K13: {=_xlfn.IFS(AND(Table[[#This Row],[Aware: Safety & Wellness Office]]="Yes",Table[[#This Row],[Aware: Monthly Meetings]]="Yes"), "Aware of office & meeting", AND(Table[[#This Row],[Aware: Safety & Wellness Office]]="Yes", Table[[#This Row],[Aware: Monthly Meetings]]="No"), "Aware of office", AND(Table[[#This Row],[Aware: Safety & Wellness Office]]="No", Table[[#This Row],[Aware: Monthly Meetings]]="Yes"), "Aware of meeting", AND(Table[[#This Row],[Aware: Safety & Wellness Office]]="No", Table[[#This Row],[Aware: Monthly Meetings]]="No"),"Unaware of office & meeting", TRUE, "Check Data")} -> Aware of office & meeting | L13: No | M13: {=_xlfn.IFS(AND(Table[[#This Row],[Aware: Safety & Wellness Office]]="Yes",Table[[#This Row],[Aware: Monthly Meetings]]="Yes",Table[[#This Row],[Attended in Past 3 Years]]="Yes"), "Aware Attendee", AND(Table[[#This Row],[Aware: Safety & Wellness Office]]="Yes",Table[[#This Row],[Aware: Monthly Meetings]]="No",Table[[#This Row],[Attended in Past 3 Years]]="Yes"), "Office Aware Attendee", AND(Table[[#This Row],[Aware: Safety & Wellness Office]]="No",Table[[#This Row],[Aware: Monthly Meetings]]="Yes",Table[[#This Row],[Attended in Past 3 Years]]="Yes"), "Meeting Aware Attendee", AND(Table[[#This Row],[Aware: Safety & Wellness Office]]="No",Table[[#This Row],[Aware: Monthly Meetings]]="No",Table[[#This Row],[Attended in Past 3 Years]]="Yes"), "Unaware Attendee", AND(Table[[#This Row],[Aware: Safety & Wellness Office]]="No",Table[[#This Row],[Aware: Monthly Meetings]]="No",Table[[#This Row],[Attended in Past 3 Years]]="No"), "Unaware Non-attendee", AND(Table[[#This Row],[Aware: Safety & Wellness Office]]="Yes",Table[[#This Row],[Aware: Monthly Meetings]]="No",Table[[#This Row],[Attended in Past 3 Years]]="No"), "Office Aware Non-attendee", AND(Table[[#This Row],[Aware: Safety & Wellness Office]]="No",Table[[#This Row],[Aware: Monthly Meetings]]="Yes",Table[[#This Row],[Attended in Past 3 Years]]="No"), "Meeting Aware Non-attendee", AND(Table[[#This Row],[Aware: Safety & Wellness Office]]="Yes",Table[[#This Row],[Aware: Monthly Meetings]]="Yes",Table[[#This Row],[Attended in Past 3 Years]]="No"), "Aware Non-attendee", TRUE, "Check Data")} -> Aware Non-attendee | N13: Location too far | O13: Time conflict | P13: No | Q13: No
A14: 13 | B14: Staff_018 | C14: Sales & Marketing | D14: Division 077 | E14: 1-5 | F14: =MATCH(Table[[#This Row],[Years of Service]], {"<1","1-5","6-10","11-20","21-30","31-40","40+"}, 0) -> 2 | G14: No | H14: Non-supervisor | I14: Yes | J14: No | K14: {=_xlfn.IFS(AND(Table[[#This Row],[Aware: Safety & Wellness Office]]="Yes",Table[[#This Row],[Aware: Monthly Meetings]]="Yes"), "Aware of office & meeting", AND(Table[[#This Row],[Aware: Safety & Wellness Office]]="Yes", Table[[#This Row],[Aware: Monthly Meetings]]="No"), "Aware of office", AND(Table[[#This Row],[Aware: Safety & Wellness Office]]="No", Table[[#This Row],[Aware: Monthly Meetings]]="Yes"), "Aware of meeting", AND(Table[[#This Row],[Aware: Safety & Wellness Office]]="No", Table[[#This Row],[Aware: Monthly Meetings]]="No"),"Unaware of office & meeting", TRUE, "Check Data")} -> Aware of office | L14: No | M14: {=_xlfn.IFS(AND(Table[[#This Row],[Aware: Safety & Wellness Office]]="Yes",Table[[#This Row],[Aware: Monthly Meetings]]="Yes",Table[[#This Row],[Attended in Past 3 Years]]="Yes"), "Aware Attendee", AND(Table[[#This Row],[Aware: Safety & Wellness Office]]="Yes",Table[[#This Row],[Aware: Monthly Meetings]]="No",Table[[#This Row],[Attended in Past 3 Years]]="Yes"), "Office Aware Attendee", AND(Table[[#This Row],[Aware: Safety & Wellness Office]]="No",Table[[#This Row],[Aware: Monthly Meetings]]="Yes",Table[[#This Row],[Attended in Past 3 Years]]="Yes"), "Meeting Aware Attendee", AND(Table[[#This Row],[Aware: Safety & Wellness Office]]="No",Table[[#This Row],[Aware: Monthly Meetings]]="No",Table[[#This Row],[Attended in Past 3 Years]]="Yes"), "Unaware Attendee", AND(Table[[#This Row],[Aware: Safety & Wellness Office]]="No",Table[[#This Row],[Aware: Monthly Meetings]]="No",Table[[#This Row],[Attended in Past 3 Years]]="No"), "Unaware Non-attendee", AND(Table[[#This Row],[Aware: Safety & Wellness Office]]="Yes",Table[[#This Row],[Aware: Monthly Meetings]]="No",Table[[#This Row],[Attended in Past 3 Years]]="No"), "Office Aware Non-attendee", AND(Table[[#This Row],[Aware: Safety & Wellness Office]]="No",Table[[#This Row],[Aware: Monthly Meetings]]="Yes",Table[[#This Row],[Attended in Past 3 Years]]="No"), "Meeting Aware Non-attendee", AND(Table[[#This Row],[Aware: Safety & Wellness Office]]="Yes",Table[[#This Row],[Aware: Monthly Meetings]]="Yes",Table[[#This Row],[Attended in Past 3 Years]]="No"), "Aware Non-attendee", TRUE, "Check Data")} -> Office Aware Non-attendee | N14: Unaware of meeting schedule | O14: Unaware | P14: Yes | Q14: Yes
A15: 14 | B15: Staff_020 | C15: Administration | D15: Division 058 | E15: 1-5 | F15: =MATCH(Table[[#This Row],[Years of Service]], {"<1","1-5","6-10","11-20","21-30","31-40","40+"}, 0) -> 2 | G15: No | H15: Non-supervisor | I15: Yes | J15: Yes | K15: {=_xlfn.IFS(AND(Table[[#This Row],[Aware: Safety & Wellness Office]]="Yes",Table[[#This Row],[Aware: Monthly Meetings]]="Yes"), "Aware of office & meeting", AND(Table[[#This Row],[Aware: Safety & Wellness Office]]="Yes", Table[[#This Row],[Aware: Monthly Meetings]]="No"), "Aware of office", AND(Table[[#This Row],[Aware: Safety & Wellness Office]]="No", Table[[#This Row],[Aware: Monthly Meetings]]="Yes"), "Aware of meeting", AND(Table[[#This Row],[Aware: Safety & Wellness Office]]="No", Table[[#This Row],[Aware: Monthly Meetings]]="No"),"Unaware of office & meeting", TRUE, "Check Data")} -> Aware of office & meeting | L15: Yes | M15: {=_xlfn.IFS(AND(Table[[#This Row],[Aware: Safety & Wellness Office]]="Yes",Table[[#This Row],[Aware: Monthly Meetings]]="Yes",Table[[#This Row],[Attended in Past 3 Years]]="Yes"), "Aware Attendee", AND(Table[[#This Row],[Aware: Safety & Wellness Office]]="Yes",Table[[#This Row],[Aware: Monthly Meetings]]="No",Table[[#This Row],[Attended in Past 3 Years]]="Yes"), "Office Aware Attendee", AND(Table[[#This Row],[Aware: Safety & Wellness Office]]="No",Table[[#This Row],[Aware: Monthly Meetings]]="Yes",Table[[#This Row],[Attended in Past 3 Years]]="Yes"), "Meeting Aware Attendee", AND(Table[[#This Row],[Aware: Safety & Wellness Office]]="No",Table[[#This Row],[Aware: Monthly Meetings]]="No",Table[[#This Row],[Attended in Past 3 Years]]="Yes"), "Unaware Attendee", AND(Table[[#This Row],[Aware: Safety & Wellness Office]]="No",Table[[#This Row],[Aware: Monthly Meetings]]="No",Table[[#This Row],[Attended in Past 3 Years]]="No"), "Unaware Non-attendee", AND(Table[[#This Row],[Aware: Safety & Wellness Office]]="Yes",Table[[#This Row],[Aware: Monthly Meetings]]="No",Table[[#This Row],[Attended in Past 3 Years]]="No"), "Office Aware Non-attendee", AND(Table[[#This Row],[Aware: Safety & Wellness Office]]="No",Table[[#This Row],[Aware: Monthly Meetings]]="Yes",Table[[#This Row],[Attended in Past 3 Years]]="No"), "Meeting Aware Non-attendee", AND(Table[[#This Row],[Aware: Safety & Wellness Office]]="Yes",Table[[#This Row],[Aware: Monthly Meetings]]="Yes",Table[[#This Row],[Attended in Past 3 Years]]="No"), "Aware Non-attendee", TRUE, "Check Data")} -> Aware Attendee | O15: NA | P15: No | Q15: No
A16: 15 | B16: Staff_026 | C16: Repairs | D16: Division 009 | E16: 1-5 | F16: =MATCH(Table[[#This Row],[Years of Service]], {"<1","1-5","6-10","11-20","21-30","31-40","40+"}, 0) -> 2 | G16: No | H16: Non-supervisor | I16: Yes | J16: Yes | K16: {=_xlfn.IFS(AND(Table[[#This Row],[Aware: Safety & Wellness Office]]="Yes",Table[[#This Row],[Aware: Monthly Meetings]]="Yes"), "Aware of office & meeting", AND(Table[[#This Row],[Aware: Safety & Wellness Office]]="Yes", Table[[#This Row],[Aware: Monthly Meetings]]="No"), "Aware of office", AND(Table[[#This Row],[Aware: Safety & Wellness Office]]="No", Table[[#This Row],[Aware: Monthly Meetings]]="Yes"), "Aware of meeting", AND(Table[[#This Row],[Aware: Safety & Wellness Office]]="No", Table[[#This Row],[Aware: Monthly Meetings]]="No"),"Unaware of office & meeting", TRUE, "Check Data")} -> Aware of office & meeting | L16: Yes | M16: {=_xlfn.IFS(AND(Table[[#This Row],[Aware: Safety & Wellness Office]]="Yes",Table[[#This Row],[Aware: Monthly Meetings]]="Yes",Table[[#This Row],[Attended in Past 3 Years]]="Yes"), "Aware Attendee", AND(Table[[#This Row],[Aware: Safety & Wellness Office]]="Yes",Table[[#This Row],[Aware: Monthly Meetings]]="No",Table[[#This Row],[Attended in Past 3 Years]]="Yes"), "Office Aware Attendee", AND(Table[[#This Row],[Aware: Safety & Wellness Office]]="No",Table[[#This Row],[Aware: Monthly Meetings]]="Yes",Table[[#This Row],[Attended in Past 3 Years]]="Yes"), "Meeting Aware Attendee", AND(Table[[#This Row],[Aware: Safety & Wellness Office]]="No",Table[[#This Row],[Aware: Monthly Meetings]]="No",Table[[#This Row],[Attended in Past 3 Years]]="Yes"), "Unaware Attendee", AND(Table[[#This Row],[Aware: Safety & Wellness Office]]="No",Table[[#This Row],[Aware: Monthly Meetings]]="No",Table[[#This Row],[Attended in Past 3 Years]]="No"), "Unaware Non-attendee", AND(Table[[#This Row],[Aware: Safety & Wellness Office]]="Yes",Table[[#This Row],[Aware: Monthly Meetings]]="No",Table[[#This Row],[Attended in Past 3 Years]]="No"), "Office Aware Non-attendee", AND(Table[[#This Row],[Aware: Safety & Wellness Office]]="No",Table[[#This Row],[Aware: Monthly Meetings]]="Yes",Table[[#This Row],[Attended in Past 3 Years]]="No"), "Meeting Aware Non-attendee", AND(Table[[#This Row],[Aware: Safety & Wellness Office]]="Yes",Table[[#This Row],[Aware: Monthly Meetings]]="Yes",Table[[#This Row],[Attended in Past 3 Years]]="No"), "Aware Non-attendee", TRUE, "Check Data")} -> Aware Attendee | O16: NA | P16: Yes | Q16: Unsure
A17: 16 | B17: Staff_027 | C17: Administration | D17: Division 043 | E17: 1-5 | F17: =MATCH(Table[[#This Row],[Years of Service]], {"<1","1-5","6-10","11-20","21-30","31-40","40+"}, 0) -> 2 | G17: No | H17: Non-supervisor | I17: Yes | J17: Yes | K17: {=_xlfn.IFS(AND(Table[[#This Row],[Aware: Safety & Wellness Office]]="Yes",Table[[#This Row],[Aware: Monthly Meetings]]="Yes"), "Aware of office & meeting", AND(Table[[#This Row],[Aware: Safety & Wellness Office]]="Yes", Table[[#This Row],[Aware: Monthly Meetings]]="No"), "Aware of office", AND(Table[[#This Row],[Aware: Safety & Wellness Office]]="No", Table[[#This Row],[Aware: Monthly Meetings]]="Yes"), "Aware of meeting", AND(Table[[#This Row],[Aware: Safety & Wellness Office]]="No", Table[[#This Row],[Aware: Monthly Meetings]]="No"),"Unaware of office & meeting", TRUE, "Check Data")} -> Aware of office & meeting | L17: No | M17: {=_xlfn.IFS(AND(Table[[#This Row],[Aware: Safety & Wellness Office]]="Yes",Table[[#This Row],[Aware: Monthly Meetings]]="Yes",Table[[#This Row],[Attended in Past 3 Years]]="Yes"), "Aware Attendee", AND(Table[[#This Row],[Aware: Safety & Wellness Office]]="Yes",Table[[#This Row],[Aware: Monthly Meetings]]="No",Table[[#This Row],[Attended in Past 3 Years]]="Yes"), "Office Aware Attendee", AND(Table[[#This Row],[Aware: Safety & Wellness Office]]="No",Table[[#This Row],[Aware: Monthly Meetings]]="Yes",Table[[#This Row],[Attended in Past 3 Years]]="Yes"), "Meeting Aware Attendee", AND(Table[[#This Row],[Aware: Safety & Wellness Office]]="No",Table[[#This Row],[Aware: Monthly Meetings]]="No",Table[[#This Row],[Attended in Past 3 Years]]="Yes"), "Unaware Attendee", AND(Table[[#This Row],[Aware: Safety & Wellness Office]]="No",Table[[#This Row],[Aware: Monthly Meetings]]="No",Table[[#This Row],[Attended in Past 3 Years]]="No"), "Unaware Non-attendee", AND(Table[[#This Row],[Aware: Safety & Wellness Office]]="Yes",Table[[#This Row],[Aware: Monthly Meetings]]="No",Table[[#This Row],[Attended in Past 3 Years]]="No"), "Office Aware Non-attendee", AND(Table[[#This Row],[Aware: Safety & Wellness Office]]="No",Table[[#This Row],[Aware: Monthly Meetings]]="Yes",Table[[#This Row],[Attended in Past 3 Years]]="No"), "Meeting Aware Non-attendee", AND(Table[[#This Row],[Aware: Safety & Wellness Office]]="Yes",Table[[#This Row],[Aware: Monthly Meetings]]="Yes",Table[[#This Row],[Attended in Past 3 Years]]="No"), "Aware Non-attendee", TRUE, "Check Data")} -> Aware Non-attendee | N17: Time conflict with shift | O17: NA | P17: Yes | Q17: Yes
A18: 17 | B18: Staff_028 | C18: Sales & Marketing | D18: Division 010 | E18: 1-5 | F18: =MATCH(Table[[#This Row],[Years of Service]], {"<1","1-5","6-10","11-20","21-30","31-40","40+"}, 0) -> 2 | G18: No | H18: Non-supervisor | I18: Yes | J18: Yes | K18: {=_xlfn.IFS(AND(Table[[#This Row],[Aware: Safety & Wellness Office]]="Yes",Table[[#This Row],[Aware: Monthly Meetings]]="Yes"), "Aware of office & meeting", AND(Table[[#This Row],[Aware: Safety & Wellness Office]]="Yes", Table[[#This Row],[Aware: Monthly Meetings]]="No"), "Aware of office", AND(Table[[#This Row],[Aware: Safety & Wellness Office]]="No", Table[[#This Row],[Aware: Monthly Meetings]]="Yes"), "Aware of meeting", AND(Table[[#This Row],[Aware: Safety & Wellness Office]]="No", Table[[#This Row],[Aware: Monthly Meetings]]="No"),"Unaware of office & meeting", TRUE, "Check Data")} -> Aware of office & meeting | L18: Yes | M18: {=_xlfn.IFS(AND(Table[[#This Row],[Aware: Safety & Wellness Office]]="Yes",Table[[#This Row],[Aware: Monthly Meetings]]="Yes",Table[[#This Row],[Attended in Past 3 Years]]="Yes"), "Aware Attendee", AND(Table[[#This Row],[Aware: Safety & Wellness Office]]="Yes",Table[[#This Row],[Aware: Monthly Meetings]]="No",Table[[#This Row],[Attended in Past 3 Years]]="Yes"), "Office Aware Attendee", AND(Table[[#This Row],[Aware: Safety & Wellness Office]]="No",Table[[#This Row],[Aware: Monthly Meetings]]="Yes",Table[[#This Row],[Attended in Past 3 Years]]="Yes"), "Meeting Aware Attendee", AND(Table[[#This Row],[Aware: Safety & Wellness Office]]="No",Table[[#This Row],[Aware: Monthly Meetings]]="No",Table[[#This Row],[Attended in Past 3 Years]]="Yes"), "Unaware Attendee", AND(Table[[#This Row],[Aware: Safety & Wellness Office]]="No",Table[[#This Row],[Aware: Monthly Meetings]]="No",Table[[#This Row],[Attended in Past 3 Years]]="No"), "Unaware Non-attendee", AND(Table[[#This Row],[Aware: Safety & Wellness Office]]="Yes",Table[[#This Row],[Aware: Monthly Meetings]]="No",Table[[#This Row],[Attended in Past 3 Years]]="No"), "Office Aware Non-attendee", AND(Table[[#This Row],[Aware: Safety & Wellness Office]]="No",Table[[#This Row],[Aware: Monthly Meetings]]="Yes",Table[[#This Row],[Attended in Past 3 Years]]="No"), "Meeting Aware Non-attendee", AND(Table[[#This Row],[Aware: Safety & Wellness Office]]="Yes",Table[[#This Row],[Aware: Monthly Meetings]]="Yes",Table[[#This Row],[Attended in Past 3 Years]]="No"), "Aware Non-attendee", TRUE, "Check Data")} -> Aware Attendee | O18: NA | P18: Yes | Q18: Yes
A19: 18 | B19: Staff_032 | C19: Sales & Marketing | D19: Division 002 | E19: 1-5 | F19: =MATCH(Table[[#This Row],[Years of Service]], {"<1","1-5","6-10","11-20","21-30","31-40","40+"}, 0) -> 2 | G19: No | H19: Non-supervisor | I19: Yes | J19: Yes | K19: {=_xlfn.IFS(AND(Table[[#This Row],[Aware: Safety & Wellness Office]]="Yes",Table[[#This Row],[Aware: Monthly Meetings]]="Yes"), "Aware of office & meeting", AND(Table[[#This Row],[Aware: Safety & Wellness Office]]="Yes", Table[[#This Row],[Aware: Monthly Meetings]]="No"), "Aware of office", AND(Table[[#This Row],[Aware: Safety & Wellness Office]]="No", Table[[#This Row],[Aware: Monthly Meetings]]="Yes"), "Aware of meeting", AND(Table[[#This Row],[Aware: Safety & Wellness Office]]="No", Table[[#This Row],[Aware: Monthly Meetings]]="No"),"Unaware of office & meeting", TRUE, "Check Data")} -> Aware of office & meeting | L19: No | M19: {=_xlfn.IFS(AND(Table[[#This Row],[Aware: Safety & Wellness Office]]="Yes",Table[[#This Row],[Aware: Monthly Meetings]]="Yes",Table[[#This Row],[Attended in Past 3 Years]]="Yes"), "Aware Attendee", AND(Table[[#This Row],[Aware: Safety & Wellness Office]]="Yes",Table[[#This Row],[Aware: Monthly Meetings]]="No",Table[[#This Row],[Attended in Past 3 Years]]="Yes"), "Office Aware Attendee", AND(Table[[#This Row],[Aware: Safety & Wellness Office]]="No",Table[[#This Row],[Aware: Monthly Meetings]]="Yes",Table[[#This Row],[Attended in Past 3 Years]]="Yes"), "Meeting Aware Attendee", AND(Table[[#This Row],[Aware: Safety & Wellness Office]]="No",Table[[#This Row],[Aware: Monthly Meetings]]="No",Table[[#This Row],[Attended in Past 3 Years]]="Yes"), "Unaware Attendee", AND(Table[[#This Row],[Aware: Safety & Wellness Office]]="No",Table[[#This Row],[Aware: Monthly Meetings]]="No",Table[[#This Row],[Attended in Past 3 Years]]="No"), "Unaware Non-attendee", AND(Table[[#This Row],[Aware: Safety & Wellness Office]]="Yes",Table[[#This Row],[Aware: Monthly Meetings]]="No",Table[[#This Row],[Attended in Past 3 Years]]="No"), "Office Aware Non-attendee", AND(Table[[#This Row],[Aware: Safety & Wellness Office]]="No",Table[[#This Row],[Aware: Monthly Meetings]]="Yes",Table[[#This Row],[Attended in Past 3 Years]]="No"), "Meeting Aware Non-attendee", AND(Table[[#This Row],[Aware: Safety & Wellness Office]]="Yes",Table[[#This Row],[Aware: Monthly Meetings]]="Yes",Table[[#This Row],[Attended in Past 3 Years]]="No"), "Aware Non-attendee", TRUE, "Check Data")} -> Aware Non-attendee | N19: Unaware of meeting schedule | O19: NA | P19: Yes | Q19: Yes
A20: 19 | B20: Staff_038 | C20: Repairs | D20: Division 090 | E20: 1-5 | F20: =MATCH(Table[[#This Row],[Years of Service]], {"<1","1-5","6-10","11-20","21-30","31-40","40+"}, 0) -> 2 | G20: Yes | H20: Supervisor | I20: Yes | J20: No | K20: {=_xlfn.IFS(AND(Table[[#This Row],[Aware: Safety & Wellness Office]]="Yes",Table[[#This Row],[Aware: Monthly Meetings]]="Yes"), "Aware of office & meeting", AND(Table[[#This Row],[Aware: Safety & Wellness Office]]="Yes", Table[[#This Row],[Aware: Monthly Meetings]]="No"), "Aware of office", AND(Table[[#This Row],[Aware: Safety & Wellness Office]]="No", Table[[#This Row],[Aware: Monthly Meetings]]="Yes"), "Aware of meeting", AND(Table[[#This Row],[Aware: Safety & Wellness Office]]="No", Table[[#This Row],[Aware: Monthly Meetings]]="No"),"Unaware of office & meeting", TRUE, "Check Data")} -> Aware of office | L20: No | M20: {=_xlfn.IFS(AND(Table[[#This Row],[Aware: Safety & Wellness Office]]="Yes",Table[[#This Row],[Aware: Monthly Meetings]]="Yes",Table[[#This Row],[Attended in Past 3 Years]]="Yes"), "Aware Attendee", AND(Table[[#This Row],[Aware: Safety & Wellness Office]]="Yes",Table[[#This Row],[Aware: Monthly Meetings]]="No",Table[[#This Row],[Attended in Past 3 Years]]="Yes"), "Office Aware Attendee", AND(Table[[#This Row],[Aware: Safety & Wellness Office]]="No",Table[[#This Row],[Aware: Monthly Meetings]]="Yes",Table[[#This Row],[Attended in Past 3 Years]]="Yes"), "Meeting Aware Attendee", AND(Table[[#This Row],[Aware: Safety & Wellness Office]]="No",Table[[#This Row],[Aware: Monthly Meetings]]="No",Table[[#This Row],[Attended in Past 3 Years]]="Yes"), "Unaware Attendee", AND(Table[[#This Row],[Aware: Safety & Wellness Office]]="No",Table[[#This Row],[Aware: Monthly Meetings]]="No",Table[[#This Row],[Attended in Past 3 Years]]="No"), "Unaware Non-attendee", AND(Table[[#This Row],[Aware: Safety & Wellness Office]]="Yes",Table[[#This Row],[Aware: Monthly Meetings]]="No",Table[[#This Row],[Attended in Past 3 Years]]="No"), "Office Aware Non-attendee", AND(Table[[#This Row],[Aware: Safety & Wellness Office]]="No",Table[[#This Row],[Aware: Monthly Meetings]]="Yes",Table[[#This Row],[Attended in Past 3 Years]]="No"), "Meeting Aware Non-attendee", AND(Table[[#This Row],[Aware: Safety & Wellness Office]]="Yes",Table[[#This Row],[Aware: Monthly Meetings]]="Yes",Table[[#This Row],[Attended in Past 3 Years]]="No"), "Aware Non-attendee", TRUE, "Check Data")} -> Office Aware Non-attendee | N20: Unaware of meeting schedule | O20: Unaware | P20: Yes | Q20: Yes
A21: 20 | B21: Staff_042 | C21: Sales & Marketing | D21: Division 095 | E21: 1-5 | F21: =MATCH(Table[[#This Row],[Years of Service]], {"<1","1-5","6-10","11-20","21-30","31-40","40+"}, 0) -> 2 | G21: No | H21: Non-supervisor | I21: No | J21: No | K21: {=_xlfn.IFS(AND(Table[[#This Row],[Aware: Safety & Wellness Office]]="Yes",Table[[#This Row],[Aware: Monthly Meetings]]="Yes"), "Aware of office & meeting", AND(Table[[#This Row],[Aware: Safety & Wellness Office]]="Yes", Table[[#This Row],[Aware: Monthly Meetings]]="No"), "Aware of office", AND(Table[[#This Row],[Aware: Safety & Wellness Office]]="No", Table[[#This Row],[Aware: Monthly Meetings]]="Yes"), "Aware of meeting", AND(Table[[#This Row],[Aware: Safety & Wellness Office]]="No", Table[[#This Row],[Aware: Monthly Meetings]]="No"),"Unaware of office & meeting", TRUE, "Check Data")} -> Unaware of office & meeting | L21: No | M21: {=_xlfn.IFS(AND(Table[[#This Row],[Aware: Safety & Wellness Office]]="Yes",Table[[#This Row],[Aware: Monthly Meetings]]="Yes",Table[[#This Row],[Attended in Past 3 Years]]="Yes"), "Aware Attendee", AND(Table[[#This Row],[Aware: Safety & Wellness Office]]="Yes",Table[[#This Row],[Aware: Monthly Meetings]]="No",Table[[#This Row],[Attended in Past 3 Years]]="Yes"), "Office Aware Attendee", AND(Table[[#This Row],[Aware: Safety & Wellness Office]]="No",Table[[#This Row],[Aware: Monthly Meetings]]="Yes",Table[[#This Row],[Attended in Past 3 Years]]="Yes"), "Meeting Aware Attendee", AND(Table[[#This Row],[Aware: Safety & Wellness Office]]="No",Table[[#This Row],[Aware: Monthly Meetings]]="No",Table[[#This Row],[Attended in Past 3 Years]]="Yes"), "Unaware Attendee", AND(Table[[#This Row],[Aware: Safety & Wellness Office]]="No",Table[[#This Row],[Aware: Monthly Meetings]]="No",Table[[#This Row],[Attended in Past 3 Years]]="No"), "Unaware Non-attendee", AND(Table[[#This Row],[Aware: Safety & Wellness Office]]="Yes",Table[[#This Row],[Aware: Monthly Meetings]]="No",Table[[#This Row],[Attended in Past 3 Years]]="No"), "Office Aware Non-attendee", AND(Table[[#This Row],[Aware: Safety & Wellness Office]]="No",Table[[#This Row],[Aware: Monthly Meetings]]="Yes",Table[[#This Row],[Attended in Past 3 Years]]="No"), "Meeting Aware Non-attendee", AND(Table[[#This Row],[Aware: Safety & Wellness Office]]="Yes",Table[[#This Row],[Aware: Monthly Meetings]]="Yes",Table[[#This Row],[Attended in Past 3 Years]]="No"), "Aware Non-attendee", TRUE, "Check Data")} -> Unaware Non-attendee | N21: Unaware of meeting schedule | O21: Unaware | P21: Yes | Q21: No
A22: 21 | B22: Staff_048 | C22: Sales & Marketing | D22: Division 092 | E22: 1-5 | F22: =MATCH(Table[[#This Row],[Years of Service]], {"<1","1-5","6-10","11-20","21-30","31-40","40+"}, 0) -> 2 | G22: Yes | H22: Supervisor | I22: Yes | J22: Yes | K22: {=_xlfn.IFS(AND(Table[[#This Row],[Aware: Safety & Wellness Office]]="Yes",Table[[#This Row],[Aware: Monthly Meetings]]="Yes"), "Aware of office & meeting", AND(Table[[#This Row],[Aware: Safety & Wellness Office]]="Yes", Table[[#This Row],[Aware: Monthly Meetings]]="No"), "Aware of office", AND(Table[[#This Row],[Aware: Safety & Wellness Office]]="No", Table[[#This Row],[Aware: Monthly Meetings]]="Yes"), "Aware of meeting", AND(Table[[#This Row],[Aware: Safety & Wellness Office]]="No", Table[[#This Row],[Aware: Monthly Meetings]]="No"),"Unaware of office & meeting", TRUE, "Check Data")} -> Aware of office & meeting | L22: No | M22: {=_xlfn.IFS(AND(Table[[#This Row],[Aware: Safety & Wellness Office]]="Yes",Table[[#This Row],[Aware: Monthly Meetings]]="Yes",Table[[#This Row],[Attended in Past 3 Years]]="Yes"), "Aware Attendee", AND(Table[[#This Row],[Aware: Safety & Wellness Office]]="Yes",Table[[#This Row],[Aware: Monthly Meetings]]="No",Table[[#This Row],[Attended in Past 3 Years]]="Yes"), "Office Aware Attendee", AND(Table[[#This Row],[Aware: Safety & Wellness Office]]="No",Table[[#This Row],[Aware: Monthly Meetings]]="Yes",Table[[#This Row],[Attended in Past 3 Years]]="Yes"), "Meeting Aware Attendee", AND(Table[[#This Row],[Aware: Safety & Wellness Office]]="No",Table[[#This Row],[Aware: Monthly Meetings]]="No",Table[[#This Row],[Attended in Past 3 Years]]="Yes"), "Unaware Attendee", AND(Table[[#This Row],[Aware: Safety & Wellness Office]]="No",Table[[#This Row],[Aware: Monthly Meetings]]="No",Table[[#This Row],[Attended in Past 3 Years]]="No"), "Unaware Non-attendee", AND(Table[[#This Row],[Aware: Safety & Wellness Office]]="Yes",Table[[#This Row],[Aware: Monthly Meetings]]="No",Table[[#This Row],[Attended in Past 3 Years]]="No"), "Office Aware Non-attendee", AND(Table[[#This Row],[Aware: Safety & Wellness Office]]="No",Table[[#This Row],[Aware: Monthly Meetings]]="Yes",Table[[#This Row],[Attended in Past 3 Years]]="No"), "Meeting Aware Non-attendee", AND(Table[[#This Row],[Aware: Safety & Wellness Office]]="Yes",Table[[#This Row],[Aware: Monthly Meetings]]="Yes",Table[[#This Row],[Attended in Past 3 Years]]="No"), "Aware Non-attendee", TRUE, "Check Data")} -> Aware Non-attendee | N22: Forgot due to no reminder | O22: Unaware | P22: No | Q22: No
A23: 22 | B23: Staff_051 | C23: Administration | D23: Division 091 | E23: 1-5 | F23: =MATCH(Table[[#This Row],[Years of Service]], {"<1","1-5","6-10","11-20","21-30","31-40","40+"}, 0) -> 2 | G23: No | H23: Non-supervisor | I23: Yes | J23: Yes | K23: {=_xlfn.IFS(AND(Table[[#This Row],[Aware: Safety & Wellness Office]]="Yes",Table[[#This Row],[Aware: Monthly Meetings]]="Yes"), "Aware of office & meeting", AND(Table[[#This Row],[Aware: Safety & Wellness Office]]="Yes", Table[[#This Row],[Aware: Monthly Meetings]]="No"), "Aware of office", AND(Table[[#This Row],[Aware: Safety & Wellness Office]]="No", Table[[#This Row],[Aware: Monthly Meetings]]="Yes"), "Aware of meeting", AND(Table[[#This Row],[Aware: Safety & Wellness Office]]="No", Table[[#This Row],[Aware: Monthly Meetings]]="No"),"Unaware of office & meeting", TRUE, "Check Data")} -> Aware of office & meeting | L23: Yes | M23: {=_xlfn.IFS(AND(Table[[#This Row],[Aware: Safety & Wellness Office]]="Yes",Table[[#This Row],[Aware: Monthly Meetings]]="Yes",Table[[#This Row],[Attended in Past 3 Years]]="Yes"), "Aware Attendee", AND(Table[[#This Row],[Aware: Safety & Wellness Office]]="Yes",Table[[#This Row],[Aware: Monthly Meetings]]="No",Table[[#This Row],[Attended in Past 3 Years]]="Yes"), "Office Aware Attendee", AND(Table[[#This Row],[Aware: Safety & Wellness Office]]="No",Table[[#This Row],[Aware: Monthly Meetings]]="Yes",Table[[#This Row],[Attended in Past 3 Years]]="Yes"), "Meeting Aware Attendee", AND(Table[[#This Row],[Aware: Safety & Wellness Office]]="No",Table[[#This Row],[Aware: Monthly Meetings]]="No",Table[[#This Row],[Attended in Past 3 Years]]="Yes"), "Unaware Attendee", AND(Table[[#This Row],[Aware: Safety & Wellness Office]]="No",Table[[#This Row],[Aware: Monthly Meetings]]="No",Table[[#This Row],[Attended in Past 3 Years]]="No"), "Unaware Non-attendee", AND(Table[[#This Row],[Aware: Safety & Wellness Office]]="Yes",Table[[#This Row],[Aware: Monthly Meetings]]="No",Table[[#This Row],[Attended in Past 3 Years]]="No"), "Office Aware Non-attendee", AND(Table[[#This Row],[Aware: Safety & Wellness Office]]="No",Table[[#This Row],[Aware: Monthly Meetings]]="Yes",Table[[#This Row],[Attended in Past 3 Years]]="No"), "Meeting Aware Non-attendee", AND(Table[[#This Row],[Aware: Safety & Wellness Office]]="Yes",Table[[#This Row],[Aware: Monthly Meetings]]="Yes",Table[[#This Row],[Attended in Past 3 Years]]="No"), "Aware Non-attendee", TRUE, "Check Data")} -> Aware Attendee | O23: Unaware | P23: Yes | Q23: Yes
A24: 23 | B24: Staff_062 | C24: Sales & Marketing | D24: Division 052 | E24: 1-5 | F24: =MATCH(Table[[#This Row],[Years of Service]], {"<1","1-5","6-10","11-20","21-30","31-40","40+"}, 0) -> 2 | G24: No | H24: Non-supervisor | I24: Yes | J24: Yes | K24: {=_xlfn.IFS(AND(Table[[#This Row],[Aware: Safety & Wellness Office]]="Yes",Table[[#This Row],[Aware: Monthly Meetings]]="Yes"), "Aware of office & meeting", AND(Table[[#This Row],[Aware: Safety & Wellness Office]]="Yes", Table[[#This Row],[Aware: Monthly Meetings]]="No"), "Aware of office", AND(Table[[#This Row],[Aware: Safety & Wellness Office]]="No", Table[[#This Row],[Aware: Monthly Meetings]]="Yes"), "Aware of meeting", AND(Table[[#This Row],[Aware: Safety & Wellness Office]]="No", Table[[#This Row],[Aware: Monthly Meetings]]="No"),"Unaware of office & meeting", TRUE, "Check Data")} -> Aware of office & meeting | L24: Yes | M24: {=_xlfn.IFS(AND(Table[[#This Row],[Aware: Safety & Wellness Office]]="Yes",Table[[#This Row],[Aware: Monthly Meetings]]="Yes",Table[[#This Row],[Attended in Past 3 Years]]="Yes"), "Aware Attendee", AND(Table[[#This Row],[Aware: Safety & Wellness Office]]="Yes",Table[[#This Row],[Aware: Monthly Meetings]]="No",Table[[#This Row],[Attended in Past 3 Years]]="Yes"), "Office Aware Attendee", AND(Table[[#This Row],[Aware: Safety & Wellness Office]]="No",Table[[#This Row],[Aware: Monthly Meetings]]="Yes",Table[[#This Row],[Attended in Past 3 Years]]="Yes"), "Meeting Aware Attendee", AND(Table[[#This Row],[Aware: Safety & Wellness Office]]="No",Table[[#This Row],[Aware: Monthly Meetings]]="No",Table[[#This Row],[Attended in Past 3 Years]]="Yes"), "Unaware Attendee", AND(Table[[#This Row],[Aware: Safety & Wellness Office]]="No",Table[[#This Row],[Aware: Monthly Meetings]]="No",Table[[#This Row],[Attended in Past 3 Years]]="No"), "Unaware Non-attendee", AND(Table[[#This Row],[Aware: Safety & Wellness Office]]="Yes",Table[[#This Row],[Aware: Monthly Meetings]]="No",Table[[#This Row],[Attended in Past 3 Years]]="No"), "Office Aware Non-attendee", AND(Table[[#This Row],[Aware: Safety & Wellness Office]]="No",Table[[#This Row],[Aware: Monthly Meetings]]="Yes",Table[[#This Row],[Attended in Past 3 Years]]="No"), "Meeting Aware Non-attendee", AND(Table[[#This Row],[Aware: Safety & Wellness Office]]="Yes",Table[[#This Row],[Aware: Monthly Meetings]]="Yes",Table[[#This Row],[Attended in Past 3 Years]]="No"), "Aware Non-attendee", TRUE, "Check Data")} -> Aware Attendee | O24: NA | P24: Yes | Q24: Yes
